File: python_study_guide/O sample 1 tensile test.txt
File Path: C:\Users\mts\Desktop\4LA2\Group 3\Test Run 1 02-29-24 17 03 24 PM\DAQ- Crosshead, … - (Timed).txt
Test: 4LA with Extensometer 44
Test Run: Test Run 1
Date: 2/29/2024 4:51:27 PM


Crosshead 	Load 	Time 	Extensometer
mm	kN	sec	mm
0.00107205482891004	0.928425048828125	0.119999997317791	-1.43062797164362E-05
0.017569787814864	1.08237731933594	1.12000000476837	0.00408109917771071
0.0341866361850407	1.13109655761719	2.11999988555908	0.0150715395648149
0.0508034863742068	1.17733203125	3.11999988555908	0.0229539200518047
0.0674203329253942	1.21945288085937	4.11999988555908	0.0310544455714989
0.0840967477415688	1.25785729980469	5.11999988555908	0.0387032669095788
0.100713594292756	1.29367529296875	6.11999988555908	0.0463688338641077
0.117390001832973	1.32687353515625	7.11999988555908	0.0540670916961972
0.134006855660118	1.36007800292969	8.11999988555908	0.0617165060248226
0.150683263200335	1.39058813476563	9.11999988555908	0.0690596716594882
0.167359670740552	1.42053051757813	10.1199998855591	0.0765378645155579
0.18397651729174	1.44897399902344	11.1199998855591	0.0840116335893981
0.200712485820986	1.47810803222656	12.1199998855591	0.0914216652745381
0.217329332372174	1.5044296875	13.1199998855591	0.0987278763204813
0.234005739912391	1.53188427734375	14.1199998855591	0.106199753645342
0.250682147452608	1.5578662109375	15.1199998855591	0.113432564830873
0.267358554992825	1.58305883789062	16.1200008392334	0.120790042274166
0.283975416095927	1.60786706542969	17.1200008392334	0.12796932423953
0.300651823636144	1.63243200683594	18.1200008392334	0.135606795083731
0.317328231176361	1.6550849609375	19.1200008392334	0.142283897730522
0.333945063175634	1.67765087890625	20.1200008392334	0.149768689880148
0.350621470715851	1.69912145996094	21.1200008392334	0.159172981511801
0.367297878256068	1.72552160644531	22.1200008392334	0.164923258125782
0.38391473935917	1.75066613769531	23.1200008392334	0.168444283190183
0.400650722440332	1.75639990234375	24.1200008392334	0.1739461440593
0.417267554439604	1.78555041503906	25.1200008392334	0.187371522770263
0.433943961979821	1.81580859375	26.1200008392334	0.198845547856763
0.450620369520038	1.837390625	27.1200008392334	0.201449409360066
0.467237230623141	1.84881066894531	28.1200008392334	0.204053139896132
0.483913638163358	1.86054614257813	29.1200008392334	0.209430916584097
0.500590016599745	1.88889489746094	30.1200008392334	0.222638511331752
0.517266453243792	1.90412915039063	31.1200008392334	0.236122170463204
0.533942831680179	1.91189343261719	32.1199989318848	0.242127833189443
0.550619268324226	1.93972265625	33.1199989318848	0.243625763687305
0.567236100323498	1.98093237304688	34.1199989318848	0.244542286964133
0.58397208340466	1.97177709960938	35.1199989318848	0.248005409957841
0.600648461841047	1.99972192382812	36.1199989318848	0.261057284660637
0.61726535204798	2.01776708984375	37.1199989318848	0.275136262644082
0.633882184047252	2.0488876953125	38.1199989318848	0.285122339846566
0.650618167128414	2.05206323242188	39.1199989318848	0.287410948658362
0.667234999127686	2.07095434570313	40.1199989318848	0.288860639557242
0.683911435771734	2.09129296875	41.1199989318848	0.294046069029719
0.700528267771006	2.09907543945313	42.1199989318848	0.29962946427986
0.717204646207392	2.11536010742187	43.1199989318848	0.305650202790275
0.73388108285144	2.13460278320313	44.1199989318848	0.320162216667086
0.750497914850712	2.1586455078125	45.1199989318848	0.331546500092372
0.767174351494759	2.15648779296875	46.1199989318848	0.334063661284745
0.783850729931146	2.18955908203125	47.1199989318848	0.336807483108714
0.800527166575193	2.18947802734375	48.1199989318848	0.343567866366357
0.817143998574466	2.22545703125	49.1199989318848	0.351787632098421
0.833820435218513	2.23776953125	50.1199989318848	0.361846061423421
0.850556360092014	2.24400073242187	51.1199989318848	0.369329936802387
0.867173250298947	2.26516772460938	52.1199989318848	0.37041908944957
0.883849628735334	2.26209985351562	53.1199989318848	0.378068041754887
0.900526065379381	2.31496069335937	54.1199989318848	0.388585962355137
0.917202443815768	2.27788647460937	55.1199989318848	0.39073548396118
0.933878880459815	2.30834912109375	56.1199989318848	0.397527503082529
0.950495712459087	2.32984643554687	57.1199989318848	0.399756274418905
0.967172149103135	2.32540454101562	58.1199989318848	0.407206709496677
0.983848585747182	2.35069458007812	59.1199989318848	0.419787917053327
1.00052496418357	2.3880361328125	60.1199989318848	0.429698440711945
1.01714173797518	2.41185791015625	61.1199989318848	0.432771950727329
1.03381823282689	2.39118603515625	62.1199989318848	0.433472159784287
1.05049461126328	2.38331469726563	63.1199989318848	0.434078508988023
1.06711150147021	2.40676293945313	64.120002746582	0.442996562924236
1.08378787990659	2.46068139648438	65.120002746582	0.455190660431981
1.10046425834298	2.4145068359375	66.120002746582	0.460663693957031
1.11714063677937	2.44370849609375	67.120002746582	0.467253645183519
1.13381713163108	2.46755004882813	68.120002746582	0.469654070911929
1.15043390542269	2.46838232421875	69.120002746582	0.478841830044985
1.1671104002744	2.48477075195313	70.120002746582	0.492784136440605
1.18384626694024	2.51838818359375	71.120002746582	0.501616392284632
1.20046315714717	2.53550634765625	72.120002746582	0.502718903589994
1.21713953558356	2.57193310546875	73.120002746582	0.503751449286938
1.23381603043526	2.547349609375	74.120002746582	0.504231953527778
1.25049240887165	2.51906567382813	75.120002746582	0.504468742292374
1.26716878730804	2.54981567382813	76.120002746582	0.511873280629516
1.28384516574442	2.57486962890625	77.120002746582	0.525208713952452
1.30046205595136	2.59977392578125	78.120002746582	0.537808868102729
1.31713843438774	2.57450415039062	79.120002746582	0.547114585060626
1.33381481282413	2.60572338867187	80.120002746582	0.550649652723223
1.35049130767584	2.60471655273437	81.120002746582	0.560163927730173
1.36710808146745	2.63930834960937	82.120002746582	0.574178295210004
1.38384406454861	2.65988671875	83.120002746582	0.577573024202138
1.40046095475554	2.68323681640625	84.120002746582	0.578914128709584
1.41713733319193	2.68352221679688	85.120002746582	0.579691608436406
1.43375422339886	2.7146630859375	86.120002746582	0.580414838623255
1.45043060183525	2.6586591796875	87.120002746582	0.581131316721439
1.46710698027164	2.681748046875	88.120002746582	0.586011505220085
1.48378347512335	2.70476684570313	89.120002746582	0.595837191212922
1.50040024891496	2.73162231445313	90.120002746582	0.598741171415895
1.51713623199612	2.72101586914063	91.120002746582	0.612610368989408
1.53381261043251	2.74346752929688	92.120002746582	0.627309258561581
1.55042950063944	2.69967822265625	93.120002746582	0.643843086436391
1.56710587907583	2.71785986328125	94.120002746582	0.650366360787302
1.58378237392753	2.74676538085938	95.120002746582	0.65219058888033
1.60045875236392	2.80578637695313	96.120002746582	0.653909461107105
1.61713513080031	2.82443212890625	97.120002746582	0.656829040963203
1.63375202100724	2.807734375	98.120002746582	0.666038715280592
1.65042839944363	2.83141918945313	99.120002746582	0.676206836942583
1.66710477788001	2.83370288085937	100.120002746582	0.679161050356925
1.68372166808695	2.8506123046875	101.120002746582	0.679822114761919
1.70039804652333	2.7975693359375	102.120002746582	0.680126540828496
1.71707442495972	2.8107919921875	103.120002746582	0.688409432768822
1.73375091981143	2.83377294921875	104.120002746582	0.701221579220146
1.75036769360304	2.85335986328125	105.120002746582	0.715515809133649
1.76704418845475	2.88028491210938	106.120002746582	0.72927464498207
1.78372056689113	2.88571704101563	107.120002746582	0.734048488084227
1.80039694532752	2.929697265625	108.120002746582	0.735690584406257
1.81707332376391	2.90932006835938	109.120002746582	0.7367740618065
1.83369021397084	2.9290693359375	110.120002746582	0.743068114388734
1.85036659240723	2.93663354492188	111.120002746582	0.749293831177056
1.86710257548839	2.89034423828125	112.120002746582	0.756196910515428
1.88371946569532	2.92118383789062	113.120002746582	0.762841082178056
1.90039584413171	2.9230673828125	114.120002746582	0.776750326622277
1.91713182721287	2.96306640625	115.120002746582	0.788971257861704
1.93374860100448	2.956466796875	116.120002746582	0.796648615505546
1.95042509585619	2.97906372070313	117.120002746582	0.797818822320551
1.96704198606312	2.99580834960938	118.120002746582	0.798456894699484
1.98377785272896	3.00994921875	119.120002746582	0.799134431872517
2.00045434758067	2.98332104492188	120.120002746582	0.79977628774941
2.01713060960174	2.98655224609375	121.120002746582	0.804111419711262
2.03374749980867	2.98746044921875	122.120002746582	0.81930129090324
2.0503643900156	3.0258046875	123.120002746582	0.832772930152714
2.06710025668144	3.03543188476563	124.120002746582	0.846253940835595
2.08377675153315	3.02604736328125	125.120002746582	0.854395388159901
2.10039364174008	3.05053100585938	126.120002746582	0.857134407851845
2.11707013659179	3.06532885742187	127.120002746582	0.857724691741168
2.13368679396808	3.074548828125	128.119995117188	0.8586366311647
2.15036328881979	3.03448364257813	129.119995117188	0.868501898366958
2.1670397836715	3.05298266601562	130.119995117188	0.878868682775646
2.18371604569256	3.06890625	131.119995117188	0.892862619366497
2.20039254054427	3.090005859375	132.119995117188	0.907710520550609
2.2170094307512	3.1178115234375	133.119995117188	0.921268481761217
2.23362632095814	3.0994736328125	134.119995117188	0.928291527088732
2.25036218762398	3.12807373046875	135.119995117188	0.930243404582143
2.26709805428982	3.15171166992188	136.119995117188	0.932061986532062
2.28371494449675	3.13580981445313	137.119995117188	0.933456874918193
2.30039143934846	3.14918823242188	138.119995117188	0.934427429456264
2.31700832955539	3.18012524414062	139.119995117188	0.9357207454741
2.33368459157646	3.14514013671875	140.119995117188	0.946377695072442
2.35036108642817	3.14459301757813	141.119995117188	0.959133554715663
2.36703758127987	3.15124926757812	142.119995117188	0.968306849244982
2.38371384330094	3.177703125	143.119995117188	0.971166882663965
2.40039033815265	3.2098173828125	144.119995117188	0.97272515995428
2.41700722835958	3.20046997070313	145.119995117188	0.973107002209872
2.43362388573587	3.21779663085938	146.119995117188	0.973759451881051
2.45035998523235	3.15973364257813	147.119995117188	0.977968680672348
2.46703648008406	3.17788598632813	148.119995117188	0.990235013887286
2.48371274210513	3.196083984375	149.119995117188	1.00480869878083
2.50032963231206	3.213416015625	150.119995117188	1.01944117341191
2.51700612716377	3.20656396484375	151.119995117188	1.03530671913177
2.53368238918483	3.23063671875	152.119995117188	1.04994175489992
2.55035888403654	3.24902807617188	153.119995117188	1.06442719697952
2.56703514605761	3.25578442382813	154.119995117188	1.07826478779316
2.58371164090931	3.21899609375	155.119995117188	1.08529103454202
2.60038813576102	3.25551196289063	156.119995117188	1.09079177491367
2.61700502596796	3.27837426757812	157.119995117188	1.09763396903872
2.63368128798902	3.2875380859375	158.119995117188	1.10896909609437
2.6504173874855	3.30133959960938	159.119995117188	1.12194113899022
2.66709364950657	3.25553735351563	160.119995117188	1.13140838220716
2.6837105397135	3.272234375	161.119995117188	1.13238207995892
2.70032742992043	3.333064453125	162.119995117188	1.13423925358802
2.71700392477214	3.28523779296875	163.119995117188	1.13540922757238
2.73368018679321	3.31993872070313	164.119995117188	1.13883777521551
2.75035668164492	3.3386708984375	165.119995117188	1.14451861009002
2.76697357185185	3.33676342773437	166.119995117188	1.14990526344627
2.78364983387291	3.30746850585937	167.119995117188	1.15071889013052
2.80032632872462	3.31251708984375	168.119995117188	1.15109921898693
2.81694321893156	3.3300537109375	169.119995117188	1.1518137762323
2.83361948095262	3.3594140625	170.119995117188	1.15222227759659
2.8503555804491	3.36220385742187	171.119995117188	1.15457980427891
2.86697247065604	3.36675854492188	172.119995117188	1.16215052548796
2.8836487326771	3.37739526367187	173.119995117188	1.17244315333664
2.90026562288404	3.38299438476563	174.119995117188	1.18503009434789
2.91700148954988	3.3430986328125	175.119995117188	1.20041868649423
2.93373758904636	3.335306640625	176.119995117188	1.21641042642295
2.95035447925329	3.33399975585938	177.119995117188	1.23240170069039
2.96697136946023	3.36357055664062	178.119995117188	1.24713266268373
2.98364763148129	3.39179272460937	179.119995117188	1.26093218568712
3.000324126333	3.39069384765625	180.119995117188	1.26594712492079
3.01700038835406	3.39743383789063	181.119995117188	1.2668747222051
3.03367688320577	3.4294228515625	182.119995117188	1.2677013874054
3.0502937734127	3.45589086914062	183.119995117188	1.26866076607257
3.06697026826441	3.41322338867188	184.119995117188	1.27595162484795
3.08364653028548	3.41673486328125	185.119995117188	1.28341093659401
3.10026342049241	3.42462084960937	186.119995117188	1.28481956198812
3.11693991534412	3.44827612304688	187.119995117188	1.28594052512199
3.13361617736518	3.47949536132813	188.119995117188	1.28680374473333
3.15029267221689	3.48089599609375	189.119995117188	1.28715997561812
3.16690956242383	3.41467700195312	190.119995117188	1.29500962793827
3.18358582444489	3.43292822265625	191.119995117188	1.31029426120222
3.20032192394137	3.45152416992188	192.119995117188	1.32515060249716
3.21699818596244	3.45844604492188	193.119995117188	1.34025444276631
3.23367468081415	3.47564916992188	194.119995117188	1.35518237948418
3.25029157102108	3.49149682617188	195.119995117188	1.36823626235127
3.26696783304214	3.4589052734375	196.119995117188	1.38302962295711
3.28370393253863	3.4644541015625	197.119995117188	1.3985934201628
3.30032082274556	3.45696264648438	198.119995117188	1.41053297556937
3.31699708476663	3.45521435546875	199.119995117188	1.41680403612554
3.33373318426311	3.480853515625	200.119995117188	1.4198599383235
3.35029046982527	3.50366479492188	201.119995117188	1.42124039120972
3.36696673184633	3.5156884765625	202.119995117188	1.42231059726328
3.38364322669804	3.49036547851563	203.119995117188	1.42273458186537
3.40031972154975	3.50664086914063	204.119995117188	1.42303027678281
3.41699598357081	3.53350073242188	205.119995117188	1.42370443791151
3.43361287377775	3.56475146484375	206.119995117188	1.42487557604909
3.45028936862946	3.51275073242188	207.119995117188	1.42883928492665
3.46696563065052	3.52792309570312	208.119995117188	1.43440719693899
3.48364212550223	3.55034448242188	209.119995117188	1.4394101453945
3.50025901570916	3.55726928710938	210.119995117188	1.44938542507589
3.51693527773023	3.5513759765625	211.119995117188	1.46360823418945
3.53367137722671	3.53818383789062	212.119995117188	1.47993944119662
3.55028826743364	3.52304125976563	213.119995117188	1.49700685869902
3.56696452945471	3.52569458007813	214.119995117188	1.5131919644773
3.58364102430642	3.53936938476562	215.119995117188	1.52888055890799
3.60031751915812	3.539111328125	216.119995117188	1.54528091661632
3.61699378117919	3.53923193359375	217.119995117188	1.5590701950714
3.63361067138612	3.55393994140625	218.119995117188	1.56856176909059
3.65028716623783	3.57304443359375	219.119995117188	1.57486007083207
3.6669634282589	3.59744946289063	220.119995117188	1.57944299280643
3.6836399231106	3.60206787109375	221.119995117188	1.58655969426036
3.70025681331754	3.59792456054688	222.119995117188	1.60105095710605
3.7169330753386	3.60328637695312	223.119995117188	1.61692593246698
3.73360957019031	3.59273510742188	224.119995117188	1.63298775441945
3.75028606504202	3.59859619140625	225.119995117188	1.64899008814245
3.76696232706308	3.60475024414063	226.119995117188	1.66490511037409
3.78357921727002	3.61668579101562	227.119995117188	1.68066995684057
3.80025571212173	3.62300463867188	228.119995117188	1.69617054052651
3.81693197414279	3.629845703125	229.119995117188	1.7084707506001
3.8336084689945	3.6160244140625	230.119995117188	1.71737349592149
3.85028496384621	3.60465454101563	231.119995117188	1.71946769114584
3.86696122586727	3.63084204101563	232.119995117188	1.72013347037137
3.88363772071898	3.66293505859375	233.119995117188	1.7209587385878
3.90031421557069	3.6087744140625	234.119995117188	1.72059773467481
3.91693087294698	3.62317919921875	235.119995117188	1.72095408197492
3.93366673961282	3.64248266601563	236.119995117188	1.72121182549745
3.95034346729517	3.66473950195313	237.119995117188	1.72178947832435
3.96701972931623	3.66836279296875	238.119995117188	1.72229495365173
3.98363638669252	3.68374633789063	239.119995117188	1.72276375815272
4.00031311437488	3.63483154296875	240.119995117188	1.72209879383445
4.01698937639594	3.67193139648437	241.119995117188	1.72300427220762
4.03366563841701	3.67393212890625	242.119995117188	1.72407529316843
4.05034236609936	3.6621572265625	243.119995117188	1.73115264624357
4.06701862812042	3.66093676757813	244.119995117188	1.7422839300707
4.08363528549671	3.6634462890625	245.119995117188	1.75605667755008
4.10031201317906	3.66771166992188	246.119995117188	1.771823852323
4.11692867055535	3.66657104492187	247.119995117188	1.78783142473549
4.13366453722119	3.66813818359375	248.119995117188	1.80395029019564
4.15034126490355	3.67369213867188	249.119995117188	1.8202387727797
4.16695792227983	3.6830517578125	250.119995117188	1.83617754373699
4.18357457965612	3.68394018554687	251.119995117188	1.85212085489184
4.20025130733848	3.69336157226563	252.119995117188	1.86816800851375
4.21698717400432	3.68835083007813	253.119995117188	1.88400561455637
4.23366343602538	3.68259350585938	254.119995117188	1.896160421893
4.25034016370773	3.68952172851563	255.119995117188	1.90241564996541
4.2670164257288	3.70814794921875	256.119995117188	1.90619099885225
4.28357347846031	3.72830249023438	257.119995117188	1.91027019172907
4.30030981078744	3.7293876953125	258.119995117188	1.91890040878206
4.3169860728085	3.73869311523437	259.119995117188	1.93169212434441
4.33366233482957	3.73913623046875	260.119995117188	1.94676523096859
4.35033906251192	3.73924780273438	261.119995117188	1.96198280900717
4.36695571988821	3.732517578125	262.119995117188	1.97810586541891
4.3835723772645	3.72638671875	263.119995117188	1.99425872415304
4.40030870959163	3.72742944335937	264.119995117188	2.01012473553419
4.41698497161269	3.72627465820312	265.119995117188	2.02624150551856
4.43366123363376	3.72187573242187	266.119995117188	2.04213173128664
4.45027835667133	3.72192651367188	267.119995117188	2.05462984740734
4.4669546186924	3.72555419921875	268.119995117188	2.06256145611405
4.48357127606869	3.74008666992188	269.119995117188	2.0671016536653
4.50024800375104	3.75736450195313	270.119995117188	2.07132962532341
4.5169242657721	3.73282788085938	271.119995117188	2.0724143832922
4.53366013243794	3.73128198242188	272.119995117188	2.07288004457951
4.5503368601203	3.73691162109375	273.119995117188	2.07311729900539
4.56689391285181	3.76174560546875	274.119995117188	2.07353988662362
4.58357017487288	3.79206713867188	275.119995117188	2.07422161474824
4.6003065072	3.81942944335937	276.119995117188	2.07519507966936
4.61698276922107	3.81335766601563	277.119995117188	2.079120837152
4.63365903124213	3.77085815429687	278.119995117188	2.09349393844604
4.65027615427971	3.7769462890625	279.119995117188	2.10809172131121
4.66695241630077	3.78084985351563	280.119995117188	2.12382897734642
4.68362867832184	3.78098876953125	281.119995117188	2.13982886634767
4.70036501064897	3.78276416015625	282.119995117188	2.15592258609831
4.71698166802526	3.78852978515625	283.119995117188	2.17192969284952
4.73359832540154	3.79284912109375	284.119995117188	2.1876790560782
4.75033465772867	3.79121997070312	285.119995117188	2.20411573536694
4.76689171046019	3.79390234375	286.119995117188	2.22036172635853
4.78356797248125	3.787642578125	287.119995117188	2.23641400225461
4.80030430480838	3.78882153320313	288.119995117188	2.24987673573196
4.81692096218467	3.781322265625	289.119995117188	2.25888937711716
4.83359722420573	3.7802646484375	290.119995117188	2.26267660036683
4.85027395188808	3.78410327148437	291.119995117188	2.26372573524714
4.86689060926437	3.798572265625	292.119995117188	2.26445333100855
4.88362647593021	3.83644873046875	293.119995117188	2.2656109649688
4.90036234259605	3.81746508789062	294.119995117188	2.26877257227898
4.91697946563363	3.82363330078125	295.119995117188	2.27747391909361
4.93359612300992	3.83041259765625	296.119995117188	2.28910613805056
4.95033245533705	3.8337529296875	297.119995117188	2.30368482880294
4.96694911271334	3.83672973632813	298.119995117188	2.31963698752224
4.98368497937918	3.83898266601562	299.119995117188	2.33570067211986
5.00036124140024	3.83907885742188	300.119995117188	2.3518695961684
5.01697836443782	3.83259155273438	301.119995117188	2.36852606758475
5.03365462645888	3.8313603515625	302.119995117188	2.38498509861529
5.05027174949646	3.83027124023438	303.119995117188	2.40146997384727
5.06694801151752	3.82417553710938	304.119995117188	2.41820304654539
5.08362427353859	3.81533666992188	305.119995117188	2.43400875478983
5.10030100122094	3.80113256835938	306.119995117188	2.44550639763474
5.11691765859723	3.803572265625	307.119995117188	2.45283776894212
5.1335939206183	3.80597338867187	308.119995117188	2.45630671270192
5.15027064830065	3.81696557617188	309.119995117188	2.45747063308954
5.16694691032171	3.82765454101563	310.119995117188	2.45838612318039
5.183563567698	3.87330590820312	311.119995117188	2.4598476011306
5.20024029538035	3.83917895507813	312.119995117188	2.46293959207833
5.21691655740142	3.84075854492188	313.119995117188	2.47242418117821
5.23359281942248	3.8491748046875	314.119995117188	2.48515582643449
5.25026954710484	3.8573232421875	315.119995117188	2.49999482184649
5.2669458091259	3.864421875	316.119995117188	2.51564662903547
5.28368167579174	3.87102099609375	317.119995117188	2.53159506246448
5.30029879882932	3.87251953125	318.119995117188	2.54777772352099
5.31691545620561	3.87407788085937	319.119995117188	2.5637224316597
5.33365132287145	3.87677001953125	320.119995117188	2.5801423471421
5.35032758489251	3.88331494140625	321.119995117188	2.59608798660338
5.36700431257486	3.8828134765625	322.119995117188	2.61162361130118
5.38362096995115	3.88191870117187	323.119995117188	2.62768822722137
5.4002976976335	3.88107202148438	324.119995117188	2.64351000078022
5.41697395965457	3.87399731445313	325.119995117188	2.65878275968134
5.43365022167563	3.87443798828125	326.119995117188	2.67218542285264
5.45026734471321	3.86778735351563	327.119995117188	2.6827696710825
5.46694360673428	3.8668466796875	328.119995117188	2.68795154988766
5.48367947340012	3.87643286132813	329.119995117188	2.69165844656527
5.50023699179292	3.8879423828125	330.119995117188	2.69475928507745
5.51691325381398	3.89682641601562	331.119995117188	2.69971531815827
5.53364912047982	3.89179809570313	332.119995117188	2.70517868921161
5.55032538250089	3.86099047851563	333.119995117188	2.70602642558515
5.56700211018324	3.8676318359375	334.119995117188	2.70631397143006
5.58361876755953	3.87734252929688	335.119995117188	2.70694307982922
5.60029502958059	3.89169262695312	336.119995117188	2.70731234923005
5.61697175726295	3.887728515625	337.119995117188	2.70756101235747
5.63364801928401	3.94839526367188	338.119995117188	2.70899338647723
5.65026514232159	3.96273217773438	339.119995117188	2.71116988733411
5.66694140434265	3.96407788085938	340.119995117188	2.71412031725049
5.68361766636372	3.9126953125	341.119995117188	2.72676139138639
5.70023478940129	3.91256323242188	342.119995117188	2.74102855473757
5.71691105142236	3.9152529296875	343.119995117188	2.75628338567913
5.73358731344342	3.9193271484375	344.119995117188	2.77204136364162
5.750204436481	3.92267700195312	345.119995117188	2.78793578036129
5.76694030314684	3.92253149414063	346.119995117188	2.80407886020839
5.78355696052313	3.91785424804688	347.119995117188	2.8207974974066
5.80017408356071	3.9152685546875	348.119995117188	2.83730402588844
5.81690995022655	3.91345336914063	349.119995117188	2.85373604856431
5.83352660760283	3.91116967773437	350.119995117188	2.87036690860987
5.85020333528519	3.90208544921875	351.119995117188	2.88738333620131
5.86687959730625	3.89321362304688	352.119995117188	2.90273339487612
5.88361546397209	3.88644653320313	353.119995117188	2.91422381997108
5.90029172599316	3.88609448242188	354.119995117188	2.92203552089632
5.91696845367551	3.89518188476563	355.119995117188	2.92732706293464
5.9335851110518	3.9058681640625	356.119995117188	2.93196365237236
5.95026137307286	3.91090185546875	357.119995117188	2.93958792462945
5.96699770539999	3.91678125	358.119995117188	2.95115984044969
5.98361436277628	3.92267358398438	359.119995117188	2.96512013301253
6.00029062479734	3.92930981445312	360.119995117188	2.98055610619485
6.0169673524797	3.93581811523438	361.119995117188	2.99648684449494
6.03358400985599	3.941951171875	362.119995117188	3.01240500994027
6.05026027187705	3.94392358398437	363.119995117188	3.02853691391647
6.0669369995594	3.94664135742188	364.119995117188	3.04482830688357
6.08361326158047	3.94805419921875	365.119995117188	3.06118838489056
6.10028952360153	3.95173803710937	366.119995117188	3.07757267728448
6.11690664663911	3.95668090820313	367.119995117188	3.09394742362201
6.13358290866017	3.95676904296875	368.119995117188	3.11001273803413
6.15025917068124	3.95550366210938	369.119995117188	3.12667503021657
6.16693589836359	3.95483325195313	370.119995117188	3.14328959211707
6.18355255573988	3.94611254882813	371.119995117188	3.15995374694467
6.20022881776094	3.94121801757813	372.119995117188	3.17405234090984
6.21696515008807	3.93473486328125	373.119995117188	3.18498886190355
6.23358180746436	3.933232421875	374.119995117188	3.19143617525697
6.25025806948543	3.93285961914063	375.119995117188	3.19483829662204
6.26693479716778	3.93833862304687	376.119995117188	3.19670233875513
6.28361105918884	3.95030029296875	377.119995117188	3.19753703661263
6.30028732120991	3.9620859375	378.119995117188	3.19880992174149
6.31696404889226	3.95733081054688	379.119995117188	3.20371659472585
6.33358070626855	3.95968139648437	380.119995117188	3.21304029785097
6.35025696828961	3.965474609375	381.119995117188	3.22512397542596
6.36699330061674	3.97004174804688	382.119995117188	3.23897367343307
6.38360995799303	3.97425268554688	383.119995117188	3.25382221490145
6.4002862200141	3.97872607421875	384.119995117188	3.26965237036347
6.41696294769645	3.98133569335937	385.119995117188	3.28578683547676
6.43357960507274	3.98415869140625	386.119995117188	3.3017813693732
6.4502558670938	3.9865146484375	387.119995117188	3.31792701035738
6.46687299013138	3.98571533203125	388.119995117188	3.33448080345988
6.48360885679722	3.98257275390625	389.119995117188	3.35106928832829
6.50028511881828	3.97992578125	390.119995117188	3.36785381659865
6.51690224185586	3.97788647460938	391.119995117188	3.38436220772564
6.53351889923215	3.97636181640625	392.119995117188	3.40092810802162
6.55025476589799	3.96881982421875	393.119995117188	3.41784884221852
6.56693149358034	3.9626611328125	394.119995117188	3.43443243764341
6.58360775560141	3.95594189453125	395.119995117188	3.44905024394393
6.60028401762247	3.94726806640625	396.119995117188	3.45914997160435
6.61696074530482	3.94360668945313	397.119995117188	3.46565595827997
6.63363700732589	3.943552734375	398.119995117188	3.46880638971925
6.65031326934695	3.9555146484375	399.119995117188	3.47068090923131
6.6669899970293	3.96234033203125	400.119995117188	3.4737279638648
6.68366625905037	3.96616162109375	401.119995117188	3.48202907480299
6.70034252107143	3.97170825195313	402.119995117188	3.49309667944908
6.71695964410901	3.97676489257812	403.119995117188	3.5059277433902
6.73363590613008	3.98068334960938	404.119995117188	3.52065777406096
6.75031216815114	3.98618872070313	405.119995117188	3.53641691617668
6.76692929118872	3.99110034179688	406.119995117188	3.55203659273684
6.78360555320978	3.99489916992187	407.119995117188	3.56820481829345
6.80028181523085	3.99805810546875	408.119995117188	3.58413229696453
6.81689893826842	3.99952416992187	409.119995117188	3.60022461973131
6.83357520028949	4.00209155273437	410.119995117188	3.61677072942257
6.85025146231055	4.00390234375	411.119995117188	3.63322999328375
6.8669281899929	4.0054755859375	412.119995117188	3.64956655539572
6.88360445201397	4.00947412109375	413.119995117188	3.66584281437099
6.90028071403503	4.01349755859375	414.119995117188	3.68219404481351
6.91689783707261	4.0162578125	415.119995117188	3.69854993186891
6.93357409909368	4.01630395507812	416.119995117188	3.71485529467463
6.95030996575952	4.01336010742188	417.119995117188	3.73165751807392
6.96698669344187	4.01194189453125	418.119995117188	3.7482485640794
6.98366295546293	4.0087734375	419.119995117188	3.76488920301199
7.00027961283922	4.00076440429688	420.119995117188	3.7806611508131
7.0168967358768	4.00082006835938	421.119995117188	3.7943902425468
7.03363260254264	3.99418798828125	422.119995117188	3.80627461709082
7.0503088645637	3.99116967773438	423.119995117188	3.81333776749671
7.06692598760128	3.99240649414063	424.119995117188	3.81796341389418
7.08360224962234	3.99802758789063	425.119995117188	3.82175459526479
7.10027851164341	4.00378955078125	426.119995117188	3.82521492429078
7.11689563468099	4.007228515625	427.119995117188	3.83098213933408
7.13357189670205	4.00920361328125	428.119995117188	3.84006882086396
7.15024815872312	4.01395361328125	429.119995117188	3.85211035609245
7.16692488640547	4.01753051757813	430.119995117188	3.86573397554457
7.18360114842653	4.01980810546875	431.119995117188	3.88072594068944
7.20021780580282	4.02422729492188	432.119995117188	3.89649532735348
7.21689453348517	4.02747436523437	433.119995117188	3.91257973387837
7.23363040015101	4.03039892578125	434.119995117188	3.92861803993583
7.2502470575273	4.0329326171875	435.119995117188	3.94483562558889
7.26692378520966	4.03602709960937	436.119995117188	3.96101363003254
7.28360004723072	4.03836401367187	437.119995117188	3.97742446511984
7.30027630925179	4.04007202148438	438.119995117188	3.99366347119212
7.31695303693414	4.0371435546875	439.119995117188	4.01020143181086
7.3336292989552	4.03432373046875	440.119995117188	4.02676220983267
7.35030556097627	4.0311318359375	441.119995117188	4.04314510524273
7.36698182299733	4.0286982421875	442.119995117188	4.05958481132984
7.38365855067968	4.02753149414063	443.119995117188	4.07599750906229
7.40027520805597	4.02464477539062	444.119995117188	4.09254990518093
7.41695147007704	4.01844580078125	445.119995117188	4.10934165120125
7.43368780240417	4.01469360351563	446.119995117188	4.12575481459498
7.45030445978045	4.00773852539063	447.119995117188	4.14004875347018
7.46692158281803	4.00107470703125	448.119995117188	4.15052240714431
7.4835978448391	3.996537109375	449.119995117188	4.15830267593265
7.50021450221539	3.99809326171875	450.119995117188	4.16266545653343
7.51695036888123	4.002521484375	451.119995117188	4.16626734659076
7.5335674919188	4.00950659179688	452.119995117188	4.16987901553512
7.55024375393987	4.01367456054687	453.119995117188	4.17289091274142
7.56692048162222	4.01902026367187	454.119995117188	4.17418219149113
7.58359674364328	4.01925146484375	455.119995117188	4.17492492124438
7.60021340101957	4.01369653320312	456.119995117188	4.17452864348888
7.61694926768541	4.02467700195313	457.119995117188	4.17492771521211
7.63368560001254	4.00287353515625	458.119995117188	4.17481223121285
7.65030225738883	4.01428369140625	459.119995117188	4.17509581893682
7.66691891476512	4.03924975585937	460.119995117188	4.17581619694829
7.68359564244747	4.06599633789062	461.119995117188	4.17638383805752
7.70027190446854	4.05374267578125	462.119995117188	4.18013194575906
7.7169481664896	4.02264404296875	463.119995117188	4.19267732650042
7.73362489417195	4.0236005859375	464.119995117188	4.20157937332988
7.75030115619302	4.02522583007813	465.119995117188	4.21076826751232
7.76697741821408	4.02855395507813	466.119995117188	4.21855971217155
7.78359454125166	4.03169458007812	467.119995117188	4.22640843316913
7.80027080327272	4.0271201171875	468.119995117188	4.23765322193503
7.81694706529379	4.02958911132813	469.119995117188	4.25267172977328
7.83362332731485	4.0327607421875	470.119995117188	4.26794029772282
7.85024091601372	4.0357529296875	471.119995117188	4.28373925387859
7.86691717803478	4.03773876953125	472.119995117188	4.29950887337327
7.88359344005585	4.04069213867187	473.119995117188	4.31589968502522
7.90026970207691	4.04196630859375	474.119995117188	4.33182017877698
7.91694596409798	4.04474340820313	475.119995117188	4.34821797534823
7.93362222611904	4.04717895507812	476.119995117188	4.36441181227565
7.95023981481791	4.04790283203125	477.119995117188	4.38064336776733
7.96697568148375	4.04945361328125	478.119995117188	4.39704302698374
7.98359233886003	4.04999682617188	479.119995117188	4.41376445814967
8.0002686008811	4.05108837890625	480.119995117188	4.4300714507699
8.01700446754694	4.05164233398438	481.119995117188	4.44635562598705
8.03362112492323	4.0538896484375	482.119995117188	4.46281488984823
8.05029831826687	4.05484912109375	483.119995117188	4.47957357391715
8.06691497564316	4.05695727539062	484.119995117188	4.49583819136024
8.08359123766422	4.05954516601563	485.119995117188	4.5124008320272
8.10026749968529	4.06104858398438	486.119995117188	4.52883029356599
8.11694376170635	4.0621328125	487.119995117188	4.54551354050636
8.13356041908264	4.06291333007812	488.119995117188	4.56177024170756
8.15023761242628	4.0621611328125	489.119995117188	4.57840971648693
8.16691387444735	4.06054296875	490.119995117188	4.59516700357199
8.18353053182364	4.05907006835938	491.119995117188	4.6119662001729
8.2002067938447	4.05673559570312	492.119995117188	4.62863128632307
8.21694266051054	4.053693359375	493.119995117188	4.64548729360104
8.23355931788683	4.04703466796875	494.119995117188	4.6616718173027
8.25023651123047	4.04501416015625	495.119995117188	4.67653200030327
8.26691277325153	4.04508154296875	496.119995117188	4.69031743705273
8.2835890352726	4.04037036132812	497.119995117188	4.70189470797777
8.30026529729366	4.03883520507812	498.119995117188	4.70949010923505
8.31694155931473	4.03718627929687	499.119995117188	4.71464637666941
8.33355821669102	4.03814575195312	500.119995117188	4.71817096695304
8.35023541003466	4.03949877929688	501.119995117188	4.72090626135468
8.3669712767005	4.04510595703125	502.119995117188	4.72255982458591
8.38358793407679	4.04810522460938	503.119995117188	4.72489930689335
8.40026419609785	4.04845458984375	504.119995117188	4.73105860874057
8.41688085347414	4.04873413085938	505.119995117188	4.74052224308252
8.4335571154952	4.05293603515625	506.119995117188	4.75257309153676
8.45023430883884	4.0546259765625	507.119995117188	4.76604606956244
8.46691057085991	4.05538720703125	508.119995117188	4.7807483933866
8.4835272282362	4.05788623046875	509.119995117188	4.79612220078707
8.50026309490204	4.05919018554687	510.119995117188	4.8116915859282
8.51687975227833	4.06033666992187	511.119995117188	4.82729496434331
8.53355601429939	4.06184326171875	512.119995117188	4.84255142509937
8.55023320764303	4.06211450195313	513.119995117188	4.85742324963212
8.5669094696641	4.05894604492187	514.119995117188	4.86948946490884
8.58358573168516	4.05953881835937	515.119995117188	4.87731536850333
8.60026199370623	4.06081640625	516.119995117188	4.88239340484142
8.61693825572729	4.06378833007813	517.119995117188	4.88654570654035
8.63361451774836	4.0672451171875	518.119995117188	4.89005213603377
8.6503503844142	4.06996459960938	519.119995117188	4.89395437762141
8.66696797311306	4.06764770507812	520.119995117188	4.90142265334725
8.68364423513412	4.06657861328125	521.119995117188	4.91290725767612
8.70032049715519	4.066935546875	522.119995117188	4.92659956216812
8.71693715453148	4.06648486328125	523.119995117188	4.94155194610357
8.73361341655254	4.06639916992188	524.119995117188	4.95737930759788
8.75028967857361	4.0646484375	525.119995117188	4.9736718647182
8.76696687191725	4.06491796875	526.119995117188	4.99002169817686
8.78358352929354	4.06798364257812	527.119995117188	5.00652566552162
8.8002597913146	4.068935546875	528.119995117188	5.02305896952748
8.81693605333567	4.06862915039062	529.119995117188	5.03950100392103
8.83361231535673	4.06656225585937	530.119995117188	5.05559612065554
8.8502885773778	4.06722827148438	531.119995117188	5.07080787792802
8.86690616607666	4.06801049804687	532.119995117188	5.08521217852831
8.88352282345295	4.0694296875	533.119995117188	5.0995578058064
8.90025869011879	4.0689404296875	534.119995117188	5.11420937255025
8.91693495213985	4.06872509765625	535.119995117188	5.12895919382572
8.93361121416092	4.067599609375	536.119995117188	5.14441914856434
8.95028747618198	4.06718115234375	537.119995117188	5.16043091192842
8.96696466952562	4.06821899414062	538.119995117188	5.17683988437057
8.98364093154669	4.06747241210938	539.119995117188	5.19307050853968
9.00031719356775	4.06485424804688	540.119995117188	5.20938355475664
9.01693385094404	4.06343237304687	541.119995117188	5.22503769025207
9.03366971760988	4.0622451171875	542.119995117188	5.24005014449358
9.05034597963095	4.06086791992187	543.119995117188	5.25533687323332
9.06690396368504	4.05963793945313	544.119995117188	5.27053512632847
9.0835802257061	4.0585908203125	545.119995117188	5.28646726161242
9.10031609237194	4.05818432617188	546.119995117188	5.30239334329963
9.11693274974823	4.0555068359375	547.119995117188	5.31832734122872
9.13360901176929	4.05482006835938	548.119995117188	5.33413607627153
9.15022566914558	4.05284814453125	549.119995117188	5.34980883821845
9.16690286248922	4.05167993164063	550.119995117188	5.36570325493813
9.18357912451029	4.04917651367187	551.119995117188	5.3817592561245
9.20025538653135	4.04792041015625	552.119995117188	5.39749814197421
9.21693164855242	4.04669995117187	553.119995117188	5.41325798258185
9.23360791057348	4.04467602539062	554.119995117188	5.42949931696057
9.25022456794977	4.04254370117188	555.119995117188	5.44551387429237
9.26690176129341	4.04090551757812	556.119995117188	5.46142924576998
9.28357802331448	4.03910864257813	557.119995117188	5.47742284834385
9.30031388998032	4.03747875976562	558.119995117188	5.49367861822248
9.31699015200138	4.03493774414062	559.119995117188	5.50980400294065
9.33366641402245	4.032572265625	560.119995117188	5.52570167928934
9.35028307139874	4.03071557617188	561.119995117188	5.5416882969439
9.36696026474237	4.02742529296875	562.119995117188	5.55801438167691
9.38363652676344	4.0246484375	563.119995117188	5.57414116337895
9.4003127887845	4.02185180664063	564.119995117188	5.59047656133771
9.41692944616079	4.0178095703125	565.119995117188	5.60667831450701
9.43360570818186	4.01502319335937	566.119995117188	5.62294013798237
9.45022236555815	4.01171728515625	567.119995117188	5.63922617584467
9.46689955890179	4.00901391601563	568.119995117188	5.6558926589787
9.48363542556763	4.00535009765625	569.119995117188	5.67214470356703
9.50025208294392	4.0019033203125	570.119995117188	5.68854669108987
9.51692834496498	3.99884765625	571.119995117188	5.70505019277334
9.53354500234127	3.99535571289063	572.119995117188	5.72149408981204
9.55022126436234	3.9919521484375	573.119995117188	5.73801808059216
9.56689845770597	3.98794165039063	574.119995117188	5.75455417856574
9.58363432437181	3.98379345703125	575.119995117188	5.77125884592533
9.6002509817481	3.9801943359375	576.119995117188	5.78798772767186
9.61692724376917	3.97719653320312	577.119995117188	5.80446142703295
9.63360350579023	3.97328271484375	578.119995117188	5.82107389345765
9.65022016316652	3.96922485351562	579.119995117188	5.83764491602778
9.66695696115494	3.96506298828125	580.119995117188	5.85439568385482
9.683633223176	3.95947705078125	581.119995117188	5.87121164426208
9.70030948519707	3.95509619140625	582.119995117188	5.88774727657437
9.71698574721813	3.94950341796875	583.119995117188	5.9046926908195
9.73360240459442	3.94395751953125	584.119995117188	5.92134660109878
9.75027866661549	3.9391533203125	585.119995117188	5.93812111765146
9.76695585995913	3.93304150390625	586.119995117188	5.95507444813848
9.78363212198019	3.92754760742188	587.119995117188	5.97184151411057
9.80030838400126	3.92222119140625	588.119995117188	5.98861556500196
9.81692504137754	3.9166396484375	589.119995117188	6.00534304976463
9.83360130339861	3.91032666015625	590.119995117188	6.02231128141284
9.85027756541967	3.90401708984375	591.119995117188	6.03909324854612
9.86695475876331	3.89741748046875	592.119995117188	6.05619931593537
9.88363102078438	3.89123266601562	593.119995117188	6.07301434502006
9.90030728280544	3.885125	594.119995117188	6.08981121331453
9.91692394018173	3.8776552734375	595.119995117188	6.10690796747804
9.9336002022028	3.87021166992188	596.119995117188	6.12375698983669
9.95027646422386	3.8614228515625	597.119995117188	6.14099437370896
9.9670123308897	3.854080078125	598.119995117188	6.15807669237256
9.98368952423334	3.845140625	599.119995117188	6.17501046508551
10.0003061816096	3.83537451171875	600.119995117188	6.19236053898931
10.0169824436307	3.82570288085937	601.119995117188	6.20946800336242
10.0336587056518	3.81692504882813	602.119995117188	6.22636871412396
10.0503945723176	3.809994140625	603.119995117188	6.24376395717263
10.0670708343387	3.80026831054687	604.119995117188	6.26083044335246
10.0836884230375	3.79225341796875	605.119995117188	6.2781092710793
10.1003050804138	3.78332153320313	606.119995117188	6.29511475563049
10.1170409470797	3.774140625	607.119995117188	6.3123507425189
10.1336576044559	3.76310986328125	608.119995117188	6.32955646142364
10.150333866477	3.75391528320313	609.119995117188	6.34671840816736
10.1670697331429	3.74378271484375	610.119995117188	6.36391947045922
10.1836873218417	3.73214477539062	611.119995117188	6.38099201023579
10.2003635838628	3.72169555664063	612.119995117188	6.39841798692942
10.2169802412391	3.7114130859375	613.119995117188	6.41572382301092
10.2336565032601	3.69979052734375	614.119995117188	6.43293606117368
10.250392369926	3.68822509765625	615.119995117188	6.45040953531861
10.267068631947	3.67658422851563	616.119995117188	6.46773539483547
10.2836862206459	3.66415625	617.119995117188	6.48504262790084
10.300362482667	3.652509765625	618.119995117188	6.50239083915949
10.317038744688	3.64027221679688	619.119995117188	6.51974510401487
10.3337150067091	3.62778369140625	620.119995117188	6.53705559670925
10.3503912687302	3.614193359375	621.119995117188	6.55450625345111
10.3670675307512	3.6017724609375	622.119995117188	6.57198298722506
10.3836851194501	3.58992016601563	623.119995117188	6.5892543643713
10.4003613814712	3.576119140625	624.119995117188	6.60672876983881
10.4170376434922	3.56317553710937	625.119995117188	6.62417523562908
10.4337139055133	3.5483818359375	626.119995117188	6.64160633459687
10.4503901675344	3.53375024414062	627.119995117188	6.65901508182287
10.4670068249106	3.51742578125	628.119995117188	6.6765402443707
10.4836244136095	3.50030078125	629.119995117188	6.69421581551433
10.5003602802753	3.48154028320313	630.119995117188	6.71194726601243
10.5170365422964	3.46167065429688	631.119995117188	6.73003541305661
10.5337128043175	3.44039819335938	632.119995117188	6.74780597910285
10.5503890663385	3.41661791992188	633.119995117188	6.76577584818006
10.5670057237148	3.392021484375	634.119995117188	6.78399996832013
10.5836829170585	3.36182543945313	635.119995117188	6.80233258754015
10.6004187837243	3.3196201171875	636.119995117188	6.82192808017135
10.6170354411006	3.27625610351563	637.119995117188	6.84137409552932
10.6337713077664	3.23826977539062	638.119995117188	6.86075584962964
10.6504475697875	3.18716552734375	639.119995117188	6.88083097338676
10.6671238318086	3.12709008789062	640.119995117188	6.90128095448017
10.6838000938296	3.0701376953125	641.119995117188	6.92173512652516
10.700536891818	3.01456323242187	642.119995117188	6.94179721176624
10.7172131538391	2.94236987304688	643.119995117188	6.96288701146841
10.7338894158602	2.86384204101563	644.119995117188	6.98455376550555
10.7505060732365	2.7576083984375	645.119995117188	7.00752204284072
10.7672419399023	2.59499975585938	646.119995117188	7.03402189537883
10.7839778065681	2.43129858398438	647.119995117188	7.06179859116673
10.8006540685892	2.36090478515625	648.119995117188	7.08355847746134
10.8172716572881	2.30747509765625	649.119995117188	7.10404152050614
10.8339479193091	2.25116796875	650.119995117188	7.12420884519815
10.8506241813302	2.19656909179688	651.119995117188	7.14464671909809
10.8673004433513	2.13956030273438	652.119995117188	7.16500170528889
10.8839767053723	2.09359448242187	653.119995117188	7.18465214595199
10.9006529673934	2.05775561523438	654.119995117188	7.20371771603823
10.917330160737	2.02399560546875	655.119995117188	7.22262123599648
10.9340064227581	1.98986633300781	656.119995117188	7.24121183156967
10.9506826847792	1.9495712890625	657.119995117188	7.26047251373529
10.9673589468002	1.9011123046875	658.119995117188	7.2800568304956
10.9840948134661	1.85656298828125	659.119995117188	7.29949120432138
11.0007710754871	1.80767834472656	660.119995117188	7.31893861666322
11.017388664186	1.76260437011719	661.119995117188	7.3380651883781
11.0340649262071	1.70343725585938	662.119995117188	7.35797546803951
11.0508007928729	1.64578796386719	663.119995117188	7.37740891054273
11.067477054894	1.5846650390625	664.119995117188	7.39718088880181
11.084153316915	1.5479833984375	665.119995117188	7.41598010063171
11.1007699742913	1.51530236816406	666.119995117188	7.43452645838261
11.1174462363124	1.47757141113281	667.119995117188	7.45311425998807
11.134123429656	1.4362080078125	668.119995117188	7.47234281152487
11.1507996916771	1.3995654296875	669.119995117188	7.49076111242175
11.1674759536982	1.36545739746094	670.119995117188	7.50922504812479
11.1841522157192	1.32880883789063	671.119995117188	7.5278296135366
11.2008284777403	1.28386169433594	672.119995117188	7.54673779010773
11.2174451351166	1.23962023925781	673.119995117188	7.56567483767867
11.2341223284602	1.19963061523437	674.119995117188	7.58423982188106
11.2508581951261	1.1633095703125	675.119995117188	7.6029347255826
11.2675344571471	1.13036669921875	676.119995117188	7.62128131464124
11.2842107191682	1.09419848632813	677.119995117188	7.63960555195808
11.3008869811893	1.05974609375	678.119995117188	7.65807274729013
11.3175632432103	1.02272808837891	679.119995117188	7.67648685723543
11.334240436554	0.9812939453125	680.119995117188	7.69528467208147
11.350916698575	0.941131103515625	681.119995117188	7.71409505978227
11.3675929605961	0.904716857910156	682.119995117188	7.73285562172532
11.3843288272619	0.864988342285156	683.119995117188	7.75177218019962
11.4008858799934	0.827570007324219	684.119995117188	7.77025194838643
11.4175621420145	0.785921875	685.119995117188	7.78931938111782
11.4342980086803	0.741789611816406	686.119995117188	7.80897913500667
11.450975202024	0.693704467773438	687.119995117188	7.82857928425074
11.467651464045	0.62754248046875	688.119995117188	7.84896872937679
11.4842681214213	0.569136596679688	689.119995117188	7.8702699393034
11.5008847787976	0.514725708007812	690.119995117188	7.89326801896095
11.5175610408187	0.440206268310547	691.119995117188	7.91919510811567
11.5205990150571	0.394337341308594	691.297973632813	7.92211852967739